<?xml version="1.0"?>
<robot name="etarob"
       xmlns:sensor="http://playerstage.sourceforge.net/gazebo/xmlschema/#sensor"
       xmlns:controller="http://playerstage.sourceforge.net/gazebo/xmlschema/#controller"
       xmlns:interface="http://playerstage.sourceforge.net/gazebo/xmlschema/#interface"
       xmlns:xacro="http://www.ros.org/wiki/xacro">

  <!-- constants -->
  <xacro:property name="M_PI" value="3.1415926535897931" />
  <xacro:property name="ns" value="etarob" />

  <!-- include gazebo files for etarob -->
  <xacro:include filename="$(find etarobtest)/urdf/test.gazebo.xacro" />

  <!-- base -->
  <xacro:property name="base_width" value="2.382" />
  <xacro:property name="base_length" value="2.543" />
  <xacro:property name="base_height" value="0.9" />
  <xacro:property name="base_simple_width" value="1.2" />
  <xacro:property name="base_simple_length" value="1.2" />
  <xacro:property name="base_simple_height" value="0.3" />

  <!-- connection -->
  <xacro:property name="connection_length" value=".6" />
  <xacro:property name="connection_width" value=".1" />
  <xacro:property name="connection_height" value=".06" />
  <xacro:property name="suspension_to_crossbar" value="0.6238" />
  <xacro:property name="suspension_offset_z" value="0.13" />

  <!-- arm -->
  <xacro:property name="arm_height" value="1.1" />
  <xacro:property name="arm_length" value=".3" />
  <xacro:property name="arm_width" value=".12" />
  <xacro:property name="arm_center_of_mass_x" value="0.296087"/>
  <xacro:property name="arm_center_of_mass_y" value="-0.028977"/>
  <xacro:property name="arm_center_of_mass_z" value="0.000000"/>

  <!-- wheel -->
  <xacro:property name="wheel_radius" value="0.376" />
  <xacro:property name="wheel_width" value="0.285" />

  <!-- drive parameters -->
  <xacro:property name="mx160_effort" value="500" />
  <xacro:property name="mx160_velocity" value="50" />

  <!-- inertia -->
  <xacro:macro name="cylinder_inertia" params="m r h">    
      <inertia  ixx="${m*(3*r*r+h*h)/12}" ixy = "0" ixz = "0"
                iyy="${m*(3*r*r+h*h)/12}" iyz = "0" izz="${m*r*r/2}" />
  </xacro:macro>
 
  <xacro:macro name="box_inertia" params="m x y z">
      <inertia  ixx="${m*(y*y+z*z)/12}" ixy = "0" ixz = "0"
                iyy="${m*(z*z+x*x)/12}" iyz = "0" izz="${m*(x*x+y*y)/12}" />
  </xacro:macro>

  <!-- base_footprint -->   
  <link name="base_footprint" />
  <joint name="footprint_to_base" type="fixed">
    <origin xyz="0 0 1.2" rpy="${M_PI/2} 0 0 "  />
    <parent link="base_footprint" />
    <child link="base_link" />
  </joint>

  <!-- base -->
  <link name="base_link">
    <inertial>
      <mass value="20.0" />
      <origin xyz="0 0 0" />
      <box_inertia m="20.0" x="${base_simple_width}" y="${base_simple_length}" z="${base_simple_height}" />
    </inertial>
    <visual>
      <origin xyz="0 0 0" rpy="0 0 0" />
      <geometry>
        <mesh filename="package://etarobtest/meshes/base_test.stl" />
      </geometry>
    </visual>
    <collision>
      <origin xyz="0 0 0" rpy="0 0 0" />
      <geometry>
        <box size="${base_width} ${base_length} ${base_height}" />
      </geometry>
    </collision>
  </link>

  <!-- base_connection (upper) -->
  <xacro:macro name= "base_upper" params="suffix *origin rot_axis">
    <joint name= "${suffix}_base_upper" type="revolute">
       <axis xyz="0 ${rot_axis} 0" />
       <limit lower="${-5*M_PI/180.0}" upper="${5*M_PI/180.0}" effort="${10*mx160_effort}" velocity="${mx160_velocity/5}"/>
       <dynamics damping="100.0" friction="10.0" />
       <parent link="base_link" />
       <child link="${suffix}_connection_upper" />
       <xacro:insert_block name="origin" />
    </joint>

    <xacro:simple_transmission name="${suffix}_base_upper" interface="hardware_interface/EffortJointInterface" />

    <link name="${suffix}_connection_upper">
      <inertial>
        <mass value="2.0" />
        <origin xyz="0 0 0" />
        <box_inertia m="2.0" x="${connection_width}" y="${connection_length}" z="${connection_height}" />
      </inertial>

      <visual>
        <origin xyz="0 0 0" rpy="0 0 0" />
	<geometry>
	  <mesh filename="package://etarobtest/meshes/upper_connection_${suffix}.stl" />	
	</geometry>
      </visual>

      <visual>
        <origin xyz="0 0 0" rpy="0 0 0" />
	<geometry>
	  <mesh filename="package://etarobtest/meshes/lower_connection_${suffix}.stl" />	
	</geometry>
      </visual>

      <collision>
        <origin xyz="0 0 0" rpy="0 0 0" />
        <geometry>
          <box size="${connection_width} ${connection_length} ${connection_height}" />
        </geometry>
      </collision>
    </link>

  </xacro:macro>

  <!-- base_connection (lower) 
  <xacro:macro name= "base_lower" params="suffix *origin rot_axis">
    <joint name= "${suffix}_base_lower" type="revolute">
       <axis xyz="0 ${rot_axis} 0" />
       <limit lower="${-5*M_PI/180.0}" upper="${5*M_PI/180.0}" effort="${10*mx160_effort}" velocity="${mx160_velocity/5}"/>
       <parent link="base_link" />
       <child link="${suffix}_connection_lower" />
       <xacro:insert_block name="origin" />
    </joint>

    <xacro:simple_transmission name="${suffix}_base_lower" interface="hardware_interface/EffortJointInterface" />

    <link name="${suffix}_connection_lower">
      <inertial>
        <mass value="2.0" />
        <origin xyz="0 0 0" />
        <box_inertia m="2.0" x="${connection_width}" y="${connection_length}" z="${connection_height}" />
      </inertial>

      <visual>
        <origin xyz="0 0 0" rpy="0 0 0" />
	<geometry>
	  <mesh filename="package://etarobtest/meshes/lower_connection_${suffix}.stl" />	
	</geometry>
      </visual>

      <collision>
        <origin xyz="0 0 0" rpy="0 0 0" />
        <geometry>
          <box size="${connection_width} ${connection_length} ${connection_height}" />
        </geometry>
      </collision>
    </link>

  </xacro:macro>-->

  <!-- arm_connection_upper--> 
  <xacro:macro name="arm_connection_upper" params="suffix *origin rot_axis mimic">
    <xacro:if value="${(mimic == 'false')}">
      <joint name="${suffix}_upper_joint" type="revolute">
        <axis xyz="0 ${rot_axis} 0" />
        <limit lower="${-10*M_PI/180.0}" upper="${10*M_PI/180.0}" effort="${10*mx160_effort}" velocity="${mx160_velocity/5}"/>
        <parent link="${suffix}_connection_upper"/>
        <child link="${suffix}_arm_upper" />
        <xacro:insert_block name="origin" />
      </joint>

      <xacro:simple_transmission name="${suffix}_upper_joint" interface="hardware_interface/EffortJointInterface" />

      <link name="${suffix}_arm_upper">
        <inertial>
          <mass value="2.0" />
          <origin xyz="0 0 0" />
          <box_inertia m="2.0" x="${arm_width}" y="${arm_length}" z="${arm_height}" />
        </inertial>

        <visual>
          <origin xyz="0 0 0" rpy="0 0 0" />
          <geometry>
            <mesh filename="package://etarobtest/meshes/arm_${suffix}_shifted.stl" />
          </geometry>
        </visual>

        <collision>
          <origin xyz="0 0 0" rpy="0 0 0" />
          <geometry>
            <box size="${arm_width} ${arm_length} ${arm_height}" />
          </geometry>
        </collision>
      </link>

    </xacro:if>

    <!--<xacro:if value="${(mimic == 'true')}">
      <joint name= "${suffix}_lower_joint" type="revolute">
        <axis xyz="0 ${rot_axis} 0" />
        <limit lower="${-10*M_PI/180.0}" upper="${10*M_PI/180.0}" effort="${10*mx160_effort}" velocity="${mx160_velocity/5}"/>
        <parent link="${suffix}_connection_lower"/>
        <child link="${suffix}_arm_upper" />
        <xacro:insert_block name="origin" />
      </joint>

      <xacro:simple_transmission name="${suffix}_lower_joint" interface="hardware_interface/EffortJointInterface" />-->

      <!--<link name="${suffix}_arm_lower">
        <inertial>
          <mass value="2.0" />
          <origin xyz="0 0 0" />
          <box_inertia m="2.0" x="${arm_width}" y="${arm_length}" z="${arm_height}" />
        </inertial>

        <visual>
          <origin xyz="0 0 0" rpy="0 0 0" />
          <geometry>
            <mesh filename="package://etarobtest/meshes/arm_${suffix}_shifted.stl" />
          </geometry>
        </visual>

        <collision>
          <origin xyz="0 0 0" rpy="0 0 0" />
          <geometry>
            <box size="${arm_width} ${arm_length} ${arm_height}" />
          </geometry>
        </collision>
      </link>

    </xacro:if>-->

  </xacro:macro>


  <!--arm_connection_lower
  <xacro:macro name= "arm_connection_lower" params="suffix *origin rot_axis">
    <joint name= "${suffix}_lower_joint" type="revolute">
       <axis xyz="0 ${rot_axis} 0" />
       <limit lower="${-5*M_PI/180.0}" upper="${5*M_PI/180.0}" effort="${10*mx160_effort}" velocity="${mx160_velocity/5}"/>
       <parent link="${suffix}_connection_lower" />
       <child link="${suffix}_arm" />
       <xacro:insert_block name="origin" />
    </joint>

    <xacro:simple_transmission name="${suffix}_lower_joint" interface="hardware_interface/EffortJointInterface" />

  </xacro:macro> --> 

  <!-- wheel --> 
  <xacro:macro name="odom_wheel_tire" params="*origin suffix rot_axis_wheel">
    <joint name="${suffix}_wheel_joint" type="continuous">
      <axis xyz="0 0 ${rot_axis_wheel}" />
      <limit effort="${100*mx160_effort}" velocity="${mx160_velocity/2}"/>
      <dynamics damping="0.0" friction="0.0" />
      <xacro:insert_block name="origin"/>
      <parent link="${suffix}_arm_upper" />
      <child link="${suffix}_wheel_link" />
    </joint>

    <xacro:simple_transmission name="${suffix}_wheel_joint" interface="hardware_interface/EffortJointInterface" />

    <link name="${suffix}_wheel_link">
      <inertial>
        <mass value="2.5" />
        <origin xyz="0 0 0" />
        <cylinder_inertia m="2.5" r="${wheel_radius}" h="${wheel_width}" />
      </inertial>

      <visual>
        <origin xyz="0 0 0" rpy="0 0 0" />
        <geometry>
          <mesh filename="package://etarobtest/meshes/wheel_${suffix}_shifted.stl" />
        </geometry>
      </visual>

      <collision>
        <geometry>
          <cylinder radius="${wheel_radius}" length="${wheel_width}" />
        </geometry>
      </collision>
    </link>

    <xacro:gazebo_wheel_link name="${suffix}_wheel_link"/>

  </xacro:macro> 

  <xacro:base_upper suffix="fl" rot_axis="1" >
    <origin xyz="0 0 0" rpy="0 0 0" />
  </xacro:base_upper>
  <xacro:base_upper suffix="fr" rot_axis="1" >
    <origin xyz="0 0 0" rpy="0 0 0" />
  </xacro:base_upper>
  <xacro:base_upper suffix="bl" rot_axis="1" >
    <origin xyz="0 0 0" rpy="0 0 0" />
  </xacro:base_upper>
  <xacro:base_upper suffix="br" rot_axis="1" >
    <origin xyz="0 0 0" rpy="0 0 0" />
  </xacro:base_upper>


  <!--<xacro:base_lower suffix="fl" rot_axis="2" >
    <origin xyz="0 0 0" rpy="0 0 0" />
  </xacro:base_lower>
  <xacro:base_lower suffix="fr" rot_axis="-1" >
    <origin xyz="0 0 0" rpy="0 0 0" />
  </xacro:base_lower>
  <xacro:base_lower suffix="bl" rot_axis="1" >
    <origin xyz="0 0 0" rpy="0 0 0" />
  </xacro:base_lower>
  <xacro:base_lower suffix="br" rot_axis="1" >
    <origin xyz="0 0 0" rpy="0 0 0" />
  </xacro:base_lower>-->

  <xacro:arm_connection_upper suffix="fl" rot_axis="1"  mimic="false">
    <origin xyz="-1.355178 0.214831 1.085205" rpy="0 0 0" />
  </xacro:arm_connection_upper>
  <xacro:arm_connection_upper suffix="fr" rot_axis="-1" mimic="false">
    <origin xyz="-1.35248 0.173899 -1.01988" rpy="0 0 0" />
  </xacro:arm_connection_upper>  
  <xacro:arm_connection_upper suffix="bl" rot_axis="1" mimic="false">
    <origin xyz="1.186923 0.173899 1.083927" rpy="0 0 0" />
  </xacro:arm_connection_upper>
  <xacro:arm_connection_upper suffix="br" rot_axis="1" mimic="false">
    <origin xyz="1.194088 0.214831 -1.006421" rpy="0 0 0" />
  </xacro:arm_connection_upper>
  <!--<xacro:arm_connection_upper suffix="fl" rot_axis="1"  mimic="true">
    <origin xyz="-1.355178 0.214831 1.085205" rpy="0 0 0" />
  </xacro:arm_connection_upper>-->
  <!--<xacro:arm_connection_upper suffix="fr" rot_axis="-1" mimic="true">
    <origin xyz="-1.35248 0.173899 -1.01988" rpy="0 0 0" />
  </xacro:arm_connection_upper>  
  <xacro:arm_connection_upper suffix="bl" rot_axis="1" mimic="true">
    <origin xyz="1.186923 0.173899 1.083927" rpy="0 0 0" />
  </xacro:arm_connection_upper>
  <xacro:arm_connection_upper suffix="br" rot_axis="1" mimic="true">
    <origin xyz="1.194088 0.214831 -1.006421" rpy="0 0 0" />
  </xacro:arm_connection_upper>-->

    <!--<xacro:arm_connection_lower suffix="fl" rot_axis="1" />
  <xacro:arm_connection_lower suffix="fr" rot_axis="-1" />
  <xacro:arm_connection_lower suffix="bl" rot_axis="1" />
  <xacro:arm_connection_lower suffix="br" rot_axis="1" />

  <xacro:arm_connection_lower suffix="fl" rot_axis="1" >
    <origin xyz="0 0 0" rpy="0 0 0" />
  </xacro:arm_connection_lower>
  <xacro:arm_connection_lower suffix="fr" rot_axis="-1" >
    <origin xyz="0 0 0" rpy="0 0 0" />
  </xacro:arm_connection_lower>
  <xacro:arm_connection_lower suffix="bl" rot_axis="1" >
    <origin xyz="0 0 0" rpy="0 0 0" />
  </xacro:arm_connection_lower>
  <xacro:arm_connection_lower suffix="br" rot_axis="1" >
    <origin xyz="0 0 0" rpy="0 0 0" />
  </xacro:arm_connection_lower>-->

  <!--<xacro:arm_connection_upper suffix="fl" rot_axis="1" >
    <origin xyz="0 0 0" rpy="0 0 0" />
  </xacro:arm_connection_upper>
  <xacro:arm_connection_upper suffix="fr" rot_axis="-1" >
    <origin xyz="0 0 0" rpy="0 0 0" />
  </xacro:arm_connection_upper>  
  <xacro:arm_connection_upper suffix="bl" rot_axis="1" >
    <origin xyz="0 0 0" rpy="0 0 0" />
  </xacro:arm_connection_upper>
  <xacro:arm_connection_upper suffix="br" rot_axis="1" >
    <origin xyz="0 0 0" rpy="0 0 0" />
  </xacro:arm_connection_upper>-->

  <xacro:odom_wheel_tire suffix="fl" rot_axis_wheel="${arm_height}" >
    <origin xyz="0 -1.086181 0.069" rpy="0 0 0" />
  </xacro:odom_wheel_tire>
  <xacro:odom_wheel_tire suffix="bl" rot_axis_wheel="-${arm_height}" >
    <origin xyz="0 -1.090562 0.069" rpy="0 0 0" />
  </xacro:odom_wheel_tire>
  <xacro:odom_wheel_tire suffix="fr" rot_axis_wheel="${arm_height}" >
    <origin xyz="0 -1.090543 -0.06982" rpy="0 0 0" />
  </xacro:odom_wheel_tire>
  <xacro:odom_wheel_tire suffix="br" rot_axis_wheel="${arm_height}" >
    <origin xyz="0 -1.086181 -0.06998" rpy="0 0 0" />
  </xacro:odom_wheel_tire>

  <!--<xacro:odom_wheel_tire suffix="fl" rot_axis_wheel="${arm_height}" >
    <origin xyz="0 0 0" rpy="0 0 0" />
  </xacro:odom_wheel_tire>
  <xacro:odom_wheel_tire suffix="fr" rot_axis_wheel="${arm_height}" >
    <origin xyz="0 0 0" rpy="0 0 0" />
  </xacro:odom_wheel_tire>
  <xacro:odom_wheel_tire suffix="bl" rot_axis_wheel="-${arm_height}" >
    <origin xyz="0 0 0" rpy="0 0 0" />
  </xacro:odom_wheel_tire>
  <xacro:odom_wheel_tire suffix="br" rot_axis_wheel="${arm_height}" >
    <origin xyz="0 0 0" rpy="0 0 0" />
  </xacro:odom_wheel_tire>-->

</robot>
